Workbook

Sheet How to use
A1: LMS Progress Tracker
A3: What this file does | B3: Shows you, in one place, who is ahead, who is behind and who is stuck.
A4: Step 1 | B4: Open the 'Team' sheet. Type each person's real name in the yellow cells. Set the project start Monday (yellow cell).
A5: Step 2 | B5: Team members update ONLY these columns on the 'Tasks' sheet: Status (I), Blocked? (J), Actual hours (L), Review rounds (M), Notes (O).
A6: Step 3 | B6: Do not type in grey columns. They are formulas (Person, Due date, Overdue).
A7: Step 4 | B7: Look at the 'Summary' sheet every Wednesday and Friday. GREEN = fine, AMBER = talk to the person, RED = help now.
A8: Blue text | B8: Cells where you type. Black text = formulas. Yellow fill = settings you should check first.
A9: Example row | B9: Task LMS-203 | Status: In review | Blocked?: (empty) | Actual hours: 9 | Review rounds: 1 | Notes: PR #14 waiting for lead
A10: Health rule | B10: RED if 3 or more overdue tasks or 2 or more blocked tasks. AMBER if 1-2 overdue or 1 blocked. Otherwise GREEN.
A11: Overdue rule | B11: A task is OVERDUE when it is not Done and today is after the last day (Friday) of its sprint.

Sheet Summary
A1: Progress summary
A2: Today: | B2: =TODAY() -> 46295
A4: By person
A5: Tag | B5: Person | C5: Tasks | D5: Done | E5: In review/testing | F5: In progress | G5: Not started | H5: Blocked | I5: Overdue | J5: % tasks done | K5: Estimated h | L5: Done h (estimate) | M5: Actual h (done tasks) | N5: Avg review rounds | O5: Health
A6: =Team!A5 -> PM | B6: =Team!B5 -> Lead (you) | C6: =COUNTIF(Tasks!$C$2:$C$65,A6) -> 3 | D6: =COUNTIFS(Tasks!$C$2:$C$65,A6,Tasks!$I$2:$I$65,"Done") -> 0 | E6: =COUNTIFS(Tasks!$C$2:$C$65,A6,Tasks!$I$2:$I$65,"In review")+COUNTIFS(Tasks!$C$2:$C$65,A6,Tasks!$I$2:$I$65,"Testing") -> 0 | F6: =COUNTIFS(Tasks!$C$2:$C$65,A6,Tasks!$I$2:$I$65,"In progress") -> 0 | G6: =COUNTIFS(Tasks!$C$2:$C$65,A6,Tasks!$I$2:$I$65,"Not started") -> 3 | H6: =COUNTIFS(Tasks!$C$2:$C$65,A6,Tasks!$J$2:$J$65,"Yes",Tasks!$I$2:$I$65,"<>Done") -> 0 | I6: =COUNTIFS(Tasks!$C$2:$C$65,A6,Tasks!$N$2:$N$65,"OVERDUE") -> 0 | J6: =IF(C6=0,0,D6/C6) -> 0 | K6: =SUMIF(Tasks!$C$2:$C$65,A6,Tasks!$F$2:$F$65) -> 9 | L6: =SUMIFS(Tasks!$F$2:$F$65,Tasks!$C$2:$C$65,A6,Tasks!$I$2:$I$65,"Done") -> 0 | M6: =SUMIFS(Tasks!$L$2:$L$65,Tasks!$C$2:$C$65,A6,Tasks!$I$2:$I$65,"Done") -> 0 | N6: =IFERROR(AVERAGEIFS(Tasks!$M$2:$M$65,Tasks!$C$2:$C$65,A6,Tasks!$I$2:$I$65,"Done"),0) -> 0 | O6: =IF(OR(I6>=3,H6>=2),"RED",IF(OR(I6>=1,H6>=1),"AMBER","GREEN")) -> GREEN
A7: =Team!A6 -> BE-1 | B7: =Team!B6 -> Name 1 | C7: =COUNTIF(Tasks!$C$2:$C$65,A7) -> 15 | D7: =COUNTIFS(Tasks!$C$2:$C$65,A7,Tasks!$I$2:$I$65,"Done") -> 6 | E7: =COUNTIFS(Tasks!$C$2:$C$65,A7,Tasks!$I$2:$I$65,"In review")+COUNTIFS(Tasks!$C$2:$C$65,A7,Tasks!$I$2:$I$65,"Testing") -> 0 | F7: =COUNTIFS(Tasks!$C$2:$C$65,A7,Tasks!$I$2:$I$65,"In progress") -> 0 | G7: =COUNTIFS(Tasks!$C$2:$C$65,A7,Tasks!$I$2:$I$65,"Not started") -> 9 | H7: =COUNTIFS(Tasks!$C$2:$C$65,A7,Tasks!$J$2:$J$65,"Yes",Tasks!$I$2:$I$65,"<>Done") -> 0 | I7: =COUNTIFS(Tasks!$C$2:$C$65,A7,Tasks!$N$2:$N$65,"OVERDUE") -> 0 | J7: =IF(C7=0,0,D7/C7) -> 0.4 | K7: =SUMIF(Tasks!$C$2:$C$65,A7,Tasks!$F$2:$F$65) -> 62 | L7: =SUMIFS(Tasks!$F$2:$F$65,Tasks!$C$2:$C$65,A7,Tasks!$I$2:$I$65,"Done") -> 17 | M7: =SUMIFS(Tasks!$L$2:$L$65,Tasks!$C$2:$C$65,A7,Tasks!$I$2:$I$65,"Done") -> 0 | N7: =IFERROR(AVERAGEIFS(Tasks!$M$2:$M$65,Tasks!$C$2:$C$65,A7,Tasks!$I$2:$I$65,"Done"),0) -> 0 | O7: =IF(OR(I7>=3,H7>=2),"RED",IF(OR(I7>=1,H7>=1),"AMBER","GREEN")) -> GREEN
A8: =Team!A7 -> BE-2 | B8: =Team!B7 -> Name 2 | C8: =COUNTIF(Tasks!$C$2:$C$65,A8) -> 12 | D8: =COUNTIFS(Tasks!$C$2:$C$65,A8,Tasks!$I$2:$I$65,"Done") -> 2 | E8: =COUNTIFS(Tasks!$C$2:$C$65,A8,Tasks!$I$2:$I$65,"In review")+COUNTIFS(Tasks!$C$2:$C$65,A8,Tasks!$I$2:$I$65,"Testing") -> 0 | F8: =COUNTIFS(Tasks!$C$2:$C$65,A8,Tasks!$I$2:$I$65,"In progress") -> 0 | G8: =COUNTIFS(Tasks!$C$2:$C$65,A8,Tasks!$I$2:$I$65,"Not started") -> 10 | H8: =COUNTIFS(Tasks!$C$2:$C$65,A8,Tasks!$J$2:$J$65,"Yes",Tasks!$I$2:$I$65,"<>Done") -> 0 | I8: =COUNTIFS(Tasks!$C$2:$C$65,A8,Tasks!$N$2:$N$65,"OVERDUE") -> 0 | J8: =IF(C8=0,0,D8/C8) -> 0.16666667 | K8: =SUMIF(Tasks!$C$2:$C$65,A8,Tasks!$F$2:$F$65) -> 60 | L8: =SUMIFS(Tasks!$F$2:$F$65,Tasks!$C$2:$C$65,A8,Tasks!$I$2:$I$65,"Done") -> 6 | M8: =SUMIFS(Tasks!$L$2:$L$65,Tasks!$C$2:$C$65,A8,Tasks!$I$2:$I$65,"Done") -> 0 | N8: =IFERROR(AVERAGEIFS(Tasks!$M$2:$M$65,Tasks!$C$2:$C$65,A8,Tasks!$I$2:$I$65,"Done"),0) -> 0 | O8: =IF(OR(I8>=3,H8>=2),"RED",IF(OR(I8>=1,H8>=1),"AMBER","GREEN")) -> GREEN
A9: =Team!A8 -> BE-3 | B9: =Team!B8 -> Name 3 | C9: =COUNTIF(Tasks!$C$2:$C$65,A9) -> 16 | D9: =COUNTIFS(Tasks!$C$2:$C$65,A9,Tasks!$I$2:$I$65,"Done") -> 7 | E9: =COUNTIFS(Tasks!$C$2:$C$65,A9,Tasks!$I$2:$I$65,"In review")+COUNTIFS(Tasks!$C$2:$C$65,A9,Tasks!$I$2:$I$65,"Testing") -> 0 | F9: =COUNTIFS(Tasks!$C$2:$C$65,A9,Tasks!$I$2:$I$65,"In progress") -> 0 | G9: =COUNTIFS(Tasks!$C$2:$C$65,A9,Tasks!$I$2:$I$65,"Not started") -> 9 | H9: =COUNTIFS(Tasks!$C$2:$C$65,A9,Tasks!$J$2:$J$65,"Yes",Tasks!$I$2:$I$65,"<>Done") -> 0 | I9: =COUNTIFS(Tasks!$C$2:$C$65,A9,Tasks!$N$2:$N$65,"OVERDUE") -> 0 | J9: =IF(C9=0,0,D9/C9) -> 0.4375 | K9: =SUMIF(Tasks!$C$2:$C$65,A9,Tasks!$F$2:$F$65) -> 60 | L9: =SUMIFS(Tasks!$F$2:$F$65,Tasks!$C$2:$C$65,A9,Tasks!$I$2:$I$65,"Done") -> 18 | M9: =SUMIFS(Tasks!$L$2:$L$65,Tasks!$C$2:$C$65,A9,Tasks!$I$2:$I$65,"Done") -> 0 | N9: =IFERROR(AVERAGEIFS(Tasks!$M$2:$M$65,Tasks!$C$2:$C$65,A9,Tasks!$I$2:$I$65,"Done"),0) -> 0 | O9: =IF(OR(I9>=3,H9>=2),"RED",IF(OR(I9>=1,H9>=1),"AMBER","GREEN")) -> GREEN
A10: =Team!A9 -> FE | B10: =Team!B9 -> Name 4 | C10: =COUNTIF(Tasks!$C$2:$C$65,A10) -> 11 | D10: =COUNTIFS(Tasks!$C$2:$C$65,A10,Tasks!$I$2:$I$65,"Done") -> 0 | E10: =COUNTIFS(Tasks!$C$2:$C$65,A10,Tasks!$I$2:$I$65,"In review")+COUNTIFS(Tasks!$C$2:$C$65,A10,Tasks!$I$2:$I$65,"Testing") -> 0 | F10: =COUNTIFS(Tasks!$C$2:$C$65,A10,Tasks!$I$2:$I$65,"In progress") -> 0 | G10: =COUNTIFS(Tasks!$C$2:$C$65,A10,Tasks!$I$2:$I$65,"Not started") -> 11 | H10: =COUNTIFS(Tasks!$C$2:$C$65,A10,Tasks!$J$2:$J$65,"Yes",Tasks!$I$2:$I$65,"<>Done") -> 0 | I10: =COUNTIFS(Tasks!$C$2:$C$65,A10,Tasks!$N$2:$N$65,"OVERDUE") -> 0 | J10: =IF(C10=0,0,D10/C10) -> 0 | K10: =SUMIF(Tasks!$C$2:$C$65,A10,Tasks!$F$2:$F$65) -> 60 | L10: =SUMIFS(Tasks!$F$2:$F$65,Tasks!$C$2:$C$65,A10,Tasks!$I$2:$I$65,"Done") -> 0 | M10: =SUMIFS(Tasks!$L$2:$L$65,Tasks!$C$2:$C$65,A10,Tasks!$I$2:$I$65,"Done") -> 0 | N10: =IFERROR(AVERAGEIFS(Tasks!$M$2:$M$65,Tasks!$C$2:$C$65,A10,Tasks!$I$2:$I$65,"Done"),0) -> 0 | O10: =IF(OR(I10>=3,H10>=2),"RED",IF(OR(I10>=1,H10>=1),"AMBER","GREEN")) -> GREEN
A11: =Team!A10 -> QA | B11: =Team!B10 -> Name 5 | C11: =COUNTIF(Tasks!$C$2:$C$65,A11) -> 7 | D11: =COUNTIFS(Tasks!$C$2:$C$65,A11,Tasks!$I$2:$I$65,"Done") -> 0 | E11: =COUNTIFS(Tasks!$C$2:$C$65,A11,Tasks!$I$2:$I$65,"In review")+COUNTIFS(Tasks!$C$2:$C$65,A11,Tasks!$I$2:$I$65,"Testing") -> 0 | F11: =COUNTIFS(Tasks!$C$2:$C$65,A11,Tasks!$I$2:$I$65,"In progress") -> 0 | G11: =COUNTIFS(Tasks!$C$2:$C$65,A11,Tasks!$I$2:$I$65,"Not started") -> 7 | H11: =COUNTIFS(Tasks!$C$2:$C$65,A11,Tasks!$J$2:$J$65,"Yes",Tasks!$I$2:$I$65,"<>Done") -> 0 | I11: =COUNTIFS(Tasks!$C$2:$C$65,A11,Tasks!$N$2:$N$65,"OVERDUE") -> 0 | J11: =IF(C11=0,0,D11/C11) -> 0 | K11: =SUMIF(Tasks!$C$2:$C$65,A11,Tasks!$F$2:$F$65) -> 48 | L11: =SUMIFS(Tasks!$F$2:$F$65,Tasks!$C$2:$C$65,A11,Tasks!$I$2:$I$65,"Done") -> 0 | M11: =SUMIFS(Tasks!$L$2:$L$65,Tasks!$C$2:$C$65,A11,Tasks!$I$2:$I$65,"Done") -> 0 | N11: =IFERROR(AVERAGEIFS(Tasks!$M$2:$M$65,Tasks!$C$2:$C$65,A11,Tasks!$I$2:$I$65,"Done"),0) -> 0 | O11: =IF(OR(I11>=3,H11>=2),"RED",IF(OR(I11>=1,H11>=1),"AMBER","GREEN")) -> GREEN
A12: Total | C12: =SUM(C6:C11) -> 64 | D12: =SUM(D6:D11) -> 15 | E12: =SUM(E6:E11) -> 0 | F12: =SUM(F6:F11) -> 0 | G12: =SUM(G6:G11) -> 49 | H12: =SUM(H6:H11) -> 0 | I12: =SUM(I6:I11) -> 0 | J12: =IF(C12=0,0,D12/C12) -> 0.234375 | K12: =SUM(K6:K11) -> 299 | L12: =SUM(L6:L11) -> 41 | M12: =SUM(M6:M11) -> 0
A15: By sprint
A16: Sprint | C16: Tasks | D16: Done | E16: In review/testing | F16: In progress | G16: Not started | H16: Blocked | I16: Overdue | J16: % tasks done | K16: Estimated h | L16: Done h (estimate) | M16: Ends
A17: =Team!A15 -> Sprint 0 - Setup | C17: =COUNTIF(Tasks!$E$2:$E$65,A17) -> 8 | D17: =COUNTIFS(Tasks!$E$2:$E$65,A17,Tasks!$I$2:$I$65,"Done") -> 4 | E17: =COUNTIFS(Tasks!$E$2:$E$65,A17,Tasks!$I$2:$I$65,"In review")+COUNTIFS(Tasks!$E$2:$E$65,A17,Tasks!$I$2:$I$65,"Testing") -> 0 | F17: =COUNTIFS(Tasks!$E$2:$E$65,A17,Tasks!$I$2:$I$65,"In progress") -> 0 | G17: =COUNTIFS(Tasks!$E$2:$E$65,A17,Tasks!$I$2:$I$65,"Not started") -> 4 | H17: =COUNTIFS(Tasks!$E$2:$E$65,A17,Tasks!$J$2:$J$65,"Yes",Tasks!$I$2:$I$65,"<>Done") -> 0 | I17: =COUNTIFS(Tasks!$E$2:$E$65,A17,Tasks!$N$2:$N$65,"OVERDUE") -> 0 | J17: =IF(C17=0,0,D17/C17) -> 0.5 | K17: =SUMIF(Tasks!$E$2:$E$65,A17,Tasks!$F$2:$F$65) -> 21 | L17: =SUMIFS(Tasks!$F$2:$F$65,Tasks!$E$2:$E$65,A17,Tasks!$I$2:$I$65,"Done") -> 9 | M17: =Team!E15 -> 46304
A18: =Team!A16 -> Sprint 1 - Accounts and Roles | C18: =COUNTIF(Tasks!$E$2:$E$65,A18) -> 11 | D18: =COUNTIFS(Tasks!$E$2:$E$65,A18,Tasks!$I$2:$I$65,"Done") -> 5 | E18: =COUNTIFS(Tasks!$E$2:$E$65,A18,Tasks!$I$2:$I$65,"In review")+COUNTIFS(Tasks!$E$2:$E$65,A18,Tasks!$I$2:$I$65,"Testing") -> 0 | F18: =COUNTIFS(Tasks!$E$2:$E$65,A18,Tasks!$I$2:$I$65,"In progress") -> 0 | G18: =COUNTIFS(Tasks!$E$2:$E$65,A18,Tasks!$I$2:$I$65,"Not started") -> 6 | H18: =COUNTIFS(Tasks!$E$2:$E$65,A18,Tasks!$J$2:$J$65,"Yes",Tasks!$I$2:$I$65,"<>Done") -> 0 | I18: =COUNTIFS(Tasks!$E$2:$E$65,A18,Tasks!$N$2:$N$65,"OVERDUE") -> 0 | J18: =IF(C18=0,0,D18/C18) -> 0.45454545 | K18: =SUMIF(Tasks!$E$2:$E$65,A18,Tasks!$F$2:$F$65) -> 50 | L18: =SUMIFS(Tasks!$F$2:$F$65,Tasks!$E$2:$E$65,A18,Tasks!$I$2:$I$65,"Done") -> 16 | M18: =Team!E16 -> 46318
A19: =Team!A17 -> Sprint 2 - Courses, Units and Home Page | C19: =COUNTIF(Tasks!$E$2:$E$65,A19) -> 11 | D19: =COUNTIFS(Tasks!$E$2:$E$65,A19,Tasks!$I$2:$I$65,"Done") -> 2 | E19: =COUNTIFS(Tasks!$E$2:$E$65,A19,Tasks!$I$2:$I$65,"In review")+COUNTIFS(Tasks!$E$2:$E$65,A19,Tasks!$I$2:$I$65,"Testing") -> 0 | F19: =COUNTIFS(Tasks!$E$2:$E$65,A19,Tasks!$I$2:$I$65,"In progress") -> 0 | G19: =COUNTIFS(Tasks!$E$2:$E$65,A19,Tasks!$I$2:$I$65,"Not started") -> 9 | H19: =COUNTIFS(Tasks!$E$2:$E$65,A19,Tasks!$J$2:$J$65,"Yes",Tasks!$I$2:$I$65,"<>Done") -> 0 | I19: =COUNTIFS(Tasks!$E$2:$E$65,A19,Tasks!$N$2:$N$65,"OVERDUE") -> 0 | J19: =IF(C19=0,0,D19/C19) -> 0.18181818 | K19: =SUMIF(Tasks!$E$2:$E$65,A19,Tasks!$F$2:$F$65) -> 52 | L19: =SUMIFS(Tasks!$F$2:$F$65,Tasks!$E$2:$E$65,A19,Tasks!$I$2:$I$65,"Done") -> 5 | M19: =Team!E17 -> 46332
A20: =Team!A18 -> Sprint 3 - Applications and Enrollment | C20: =COUNTIF(Tasks!$E$2:$E$65,A20) -> 9 | D20: =COUNTIFS(Tasks!$E$2:$E$65,A20,Tasks!$I$2:$I$65,"Done") -> 2 | E20: =COUNTIFS(Tasks!$E$2:$E$65,A20,Tasks!$I$2:$I$65,"In review")+COUNTIFS(Tasks!$E$2:$E$65,A20,Tasks!$I$2:$I$65,"Testing") -> 0 | F20: =COUNTIFS(Tasks!$E$2:$E$65,A20,Tasks!$I$2:$I$65,"In progress") -> 0 | G20: =COUNTIFS(Tasks!$E$2:$E$65,A20,Tasks!$I$2:$I$65,"Not started") -> 7 | H20: =COUNTIFS(Tasks!$E$2:$E$65,A20,Tasks!$J$2:$J$65,"Yes",Tasks!$I$2:$I$65,"<>Done") -> 0 | I20: =COUNTIFS(Tasks!$E$2:$E$65,A20,Tasks!$N$2:$N$65,"OVERDUE") -> 0 | J20: =IF(C20=0,0,D20/C20) -> 0.22222222 | K20: =SUMIF(Tasks!$E$2:$E$65,A20,Tasks!$F$2:$F$65) -> 37 | L20: =SUMIFS(Tasks!$F$2:$F$65,Tasks!$E$2:$E$65,A20,Tasks!$I$2:$I$65,"Done") -> 4 | M20: =Team!E18 -> 46339
A21: =Team!A19 -> Sprint 4 - Assessments and Feedback | C21: =COUNTIF(Tasks!$E$2:$E$65,A21) -> 8 | D21: =COUNTIFS(Tasks!$E$2:$E$65,A21,Tasks!$I$2:$I$65,"Done") -> 1 | E21: =COUNTIFS(Tasks!$E$2:$E$65,A21,Tasks!$I$2:$I$65,"In review")+COUNTIFS(Tasks!$E$2:$E$65,A21,Tasks!$I$2:$I$65,"Testing") -> 0 | F21: =COUNTIFS(Tasks!$E$2:$E$65,A21,Tasks!$I$2:$I$65,"In progress") -> 0 | G21: =COUNTIFS(Tasks!$E$2:$E$65,A21,Tasks!$I$2:$I$65,"Not started") -> 7 | H21: =COUNTIFS(Tasks!$E$2:$E$65,A21,Tasks!$J$2:$J$65,"Yes",Tasks!$I$2:$I$65,"<>Done") -> 0 | I21: =COUNTIFS(Tasks!$E$2:$E$65,A21,Tasks!$N$2:$N$65,"OVERDUE") -> 0 | J21: =IF(C21=0,0,D21/C21) -> 0.125 | K21: =SUMIF(Tasks!$E$2:$E$65,A21,Tasks!$F$2:$F$65) -> 42 | L21: =SUMIFS(Tasks!$F$2:$F$65,Tasks!$E$2:$E$65,A21,Tasks!$I$2:$I$65,"Done") -> 4 | M21: =Team!E19 -> 46353
A22: =Team!A20 -> Sprint 5 - Attendance | C22: =COUNTIF(Tasks!$E$2:$E$65,A22) -> 8 | D22: =COUNTIFS(Tasks!$E$2:$E$65,A22,Tasks!$I$2:$I$65,"Done") -> 1 | E22: =COUNTIFS(Tasks!$E$2:$E$65,A22,Tasks!$I$2:$I$65,"In review")+COUNTIFS(Tasks!$E$2:$E$65,A22,Tasks!$I$2:$I$65,"Testing") -> 0 | F22: =COUNTIFS(Tasks!$E$2:$E$65,A22,Tasks!$I$2:$I$65,"In progress") -> 0 | G22: =COUNTIFS(Tasks!$E$2:$E$65,A22,Tasks!$I$2:$I$65,"Not started") -> 7 | H22: =COUNTIFS(Tasks!$E$2:$E$65,A22,Tasks!$J$2:$J$65,"Yes",Tasks!$I$2:$I$65,"<>Done") -> 0 | I22: =COUNTIFS(Tasks!$E$2:$E$65,A22,Tasks!$N$2:$N$65,"OVERDUE") -> 0 | J22: =IF(C22=0,0,D22/C22) -> 0.125 | K22: =SUMIF(Tasks!$E$2:$E$65,A22,Tasks!$F$2:$F$65) -> 39 | L22: =SUMIFS(Tasks!$F$2:$F$65,Tasks!$E$2:$E$65,A22,Tasks!$I$2:$I$65,"Done") -> 3 | M22: =Team!E20 -> 46360
A23: =Team!A21 -> Sprint 6 - Dashboards, Polish and Release | C23: =COUNTIF(Tasks!$E$2:$E$65,A23) -> 9 | D23: =COUNTIFS(Tasks!$E$2:$E$65,A23,Tasks!$I$2:$I$65,"Done") -> 0 | E23: =COUNTIFS(Tasks!$E$2:$E$65,A23,Tasks!$I$2:$I$65,"In review")+COUNTIFS(Tasks!$E$2:$E$65,A23,Tasks!$I$2:$I$65,"Testing") -> 0 | F23: =COUNTIFS(Tasks!$E$2:$E$65,A23,Tasks!$I$2:$I$65,"In progress") -> 0 | G23: =COUNTIFS(Tasks!$E$2:$E$65,A23,Tasks!$I$2:$I$65,"Not started") -> 9 | H23: =COUNTIFS(Tasks!$E$2:$E$65,A23,Tasks!$J$2:$J$65,"Yes",Tasks!$I$2:$I$65,"<>Done") -> 0 | I23: =COUNTIFS(Tasks!$E$2:$E$65,A23,Tasks!$N$2:$N$65,"OVERDUE") -> 0 | J23: =IF(C23=0,0,D23/C23) -> 0 | K23: =SUMIF(Tasks!$E$2:$E$65,A23,Tasks!$F$2:$F$65) -> 58 | L23: =SUMIFS(Tasks!$F$2:$F$65,Tasks!$E$2:$E$65,A23,Tasks!$I$2:$I$65,"Done") -> 0 | M23: =Team!E21 -> 46374
A25: Note: 'Done h (estimate)' adds the estimated hours of finished tasks. Compare it with 'Actual h' to see who under- or over-estimates.

Sheet Team
A1: Team and settings
A2: Project start (a Monday) | B2: 46300 | C2: Assumption: kick-off on the first Monday after 29 Sep 2026. Change if your start date is different.
A4: Tag | B4: Person (type name) | C4: Main job | D4: Main apps they own
A5: PM | B5: Lead (you) | C5: Plans, reviews every pull request, removes blockers, runs demos | D5: All (reviewer)
A6: BE-1 | B6: Name 1 | C6: Foundation and security: user model, roles, mixins, sensitive logic | D6: accounts, attendance
A7: BE-2 | B7: Name 2 | C7: Courses and applications, admin pages, deployment | D7: courses, enrollments
A8: BE-3 | B8: Name 3 | C8: Login pages, marks, reports, data rules | D8: assessments, core
A9: FE | B9: Name 4 | C9: Templates, Bootstrap, how every page looks and feels | D9: templates/, static/
A10: QA | B10: Name 5 | C10: Tests, bug reports, user acceptance testing | D10: tests/
A13: Sprint calendar
A14: Sprint | B14: Start week (0 = week 1) | C14: End week (weeks from start) | D14: Starts (Monday) | E14: Ends (Friday)
A15: Sprint 0 - Setup | B15: 0 | C15: 1 | D15: =$B$2+7*B15 -> 46300 | E15: =$B$2+7*C15-3 -> 46304
A16: Sprint 1 - Accounts and Roles | B16: 1 | C16: 3 | D16: =$B$2+7*B16 -> 46307 | E16: =$B$2+7*C16-3 -> 46318
A17: Sprint 2 - Courses, Units and Home Page | B17: 3 | C17: 5 | D17: =$B$2+7*B17 -> 46321 | E17: =$B$2+7*C17-3 -> 46332
A18: Sprint 3 - Applications and Enrollment | B18: 5 | C18: 6 | D18: =$B$2+7*B18 -> 46335 | E18: =$B$2+7*C18-3 -> 46339
A19: Sprint 4 - Assessments and Feedback | B19: 6 | C19: 8 | D19: =$B$2+7*B19 -> 46342 | E19: =$B$2+7*C19-3 -> 46353
A20: Sprint 5 - Attendance | B20: 8 | C20: 9 | D20: =$B$2+7*B20 -> 46356 | E20: =$B$2+7*C20-3 -> 46360
A21: Sprint 6 - Dashboards, Polish and Release | B21: 9 | C21: 11 | D21: =$B$2+7*B21 -> 46363 | E21: =$B$2+7*C21-3 -> 46374

Sheet Tasks
A1: ID | B1: Task | C1: Owner tag | D1: Person | E1: Sprint | F1: Estimate (h) | G1: Depends on | H1: Priority | I1: Status | J1: Blocked? | K1: Due (sprint end) | L1: Actual hours | M1: Review rounds | N1: Overdue? | O1: Notes
A2: LMS-001 | B2: Create GitHub repo, branch protection (main/develop), .gitignore, README | C2: PM | D2: =IFERROR(INDEX(Team!$B$5:$B$10,MATCH(C2,Team!$A$5:$A$10,0)),"") -> Lead (you) | E2: Sprint 0 - Setup | F2: 1 | H2: High | I2: Not started | K2: =IFERROR(INDEX(Team!$E$15:$E$21,MATCH(E2,Team!$A$15:$A$21,0)),"") -> 46304 | N2: =IF(AND(I2<>"Done",K2<>"",K2<TODAY()),"OVERDUE","")
A3: LMS-002 | B3: Create Django project 'config' with split settings (base/dev/prod), django-environ, .env.example | C3: BE-1 | D3: =IFERROR(INDEX(Team!$B$5:$B$10,MATCH(C3,Team!$A$5:$A$10,0)),"") -> Name 1 | E3: Sprint 0 - Setup | F3: 3 | G3: LMS-001 | H3: High | I3: Done | K3: =IFERROR(INDEX(Team!$E$15:$E$21,MATCH(E3,Team!$A$15:$A$21,0)),"") -> 46304 | N3: =IF(AND(I3<>"Done",K3<>"",K3<TODAY()),"OVERDUE","") | O3: Provided in the starter repo - owner: read it, ask questions, improve via PR
A4: LMS-003 | B4: Set up PostgreSQL (local or docker-compose) and connect Django to it | C4: BE-3 | D4: =IFERROR(INDEX(Team!$B$5:$B$10,MATCH(C4,Team!$A$5:$A$10,0)),"") -> Name 3 | E4: Sprint 0 - Setup | F4: 2 | G4: LMS-002 | H4: High | I4: Done | K4: =IFERROR(INDEX(Team!$E$15:$E$21,MATCH(E4,Team!$A$15:$A$21,0)),"") -> 46304 | N4: =IF(AND(I4<>"Done",K4<>"",K4<TODAY()),"OVERDUE","") | O4: Provided in the starter repo - owner: read it, ask questions, improve via PR
A5: LMS-004 | B5: Create the 6 apps (core, accounts, courses, enrollments, assessments, attendance) and register them | C5: BE-1 | D5: =IFERROR(INDEX(Team!$B$5:$B$10,MATCH(C5,Team!$A$5:$A$10,0)),"") -> Name 1 | E5: Sprint 0 - Setup | F5: 1 | G5: LMS-002 | H5: High | I5: Done | K5: =IFERROR(INDEX(Team!$E$15:$E$21,MATCH(E5,Team!$A$15:$A$21,0)),"") -> 46304 | N5: =IF(AND(I5<>"Done",K5<>"",K5<TODAY()),"OVERDUE","") | O5: Provided in the starter repo - owner: read it, ask questions, improve via PR
A6: LMS-005 | B6: Base template: Bootstrap 5, navbar that changes per role, messages and pagination partials | C6: FE | D6: =IFERROR(INDEX(Team!$B$5:$B$10,MATCH(C6,Team!$A$5:$A$10,0)),"") -> Name 4 | E6: Sprint 0 - Setup | F6: 4 | G6: LMS-004 | H6: High | I6: Not started | K6: =IFERROR(INDEX(Team!$E$15:$E$21,MATCH(E6,Team!$A$15:$A$21,0)),"") -> 46304 | N6: =IF(AND(I6<>"Done",K6<>"",K6<TODAY()),"OVERDUE","") | O6: Basic version in the starter repo - finish it
A7: LMS-006 | B7: Add ruff/black, pre-commit and a GitHub Actions workflow that runs tests on every PR | C7: BE-2 | D7: =IFERROR(INDEX(Team!$B$5:$B$10,MATCH(C7,Team!$A$5:$A$10,0)),"") -> Name 2 | E7: Sprint 0 - Setup | F7: 3 | G7: LMS-001 | H7: Medium | I7: Done | K7: =IFERROR(INDEX(Team!$E$15:$E$21,MATCH(E7,Team!$A$15:$A$21,0)),"") -> 46304 | N7: =IF(AND(I7<>"Done",K7<>"",K7<TODAY()),"OVERDUE","") | O7: Provided in the starter repo - owner: read it, ask questions, improve via PR
A8: LMS-007 | B8: Create Slack channels, connect GitHub app, build the standup workflow and task board (see Slack section) | C8: PM | D8: =IFERROR(INDEX(Team!$B$5:$B$10,MATCH(C8,Team!$A$5:$A$10,0)),"") -> Lead (you) | E8: Sprint 0 - Setup | F8: 2 | H8: High | I8: Not started | K8: =IFERROR(INDEX(Team!$E$15:$E$21,MATCH(E8,Team!$A$15:$A$21,0)),"") -> 46304 | N8: =IF(AND(I8<>"Done",K8<>"",K8<TODAY()),"OVERDUE","")
A9: LMS-008 | B9: Set up pytest + factory-boy and write the test-case checklist for workflows A to E | C9: QA | D9: =IFERROR(INDEX(Team!$B$5:$B$10,MATCH(C9,Team!$A$5:$A$10,0)),"") -> Name 5 | E9: Sprint 0 - Setup | F9: 5 | G9: LMS-004 | H9: Medium | I9: Not started | K9: =IFERROR(INDEX(Team!$E$15:$E$21,MATCH(E9,Team!$A$15:$A$21,0)),"") -> 46304 | N9: =IF(AND(I9<>"Done",K9<>"",K9<TODAY()),"OVERDUE","") | O9: Basic version in the starter repo - finish it
A10: LMS-101 | B10: Custom User model (role, phone, photo) - MUST be done before the first migrate | C10: BE-1 | D10: =IFERROR(INDEX(Team!$B$5:$B$10,MATCH(C10,Team!$A$5:$A$10,0)),"") -> Name 1 | E10: Sprint 1 - Accounts and Roles | F10: 3 | G10: LMS-004 | H10: High | I10: Done | K10: =IFERROR(INDEX(Team!$E$15:$E$21,MATCH(E10,Team!$A$15:$A$21,0)),"") -> 46318 | N10: =IF(AND(I10<>"Done",K10<>"",K10<TODAY()),"OVERDUE","") | O10: Provided in the starter repo - owner: read it, ask questions, improve via PR
A11: LMS-102 | B11: FacilitatorProfile and StudentProfile models + signal that creates the profile automatically | C11: BE-1 | D11: =IFERROR(INDEX(Team!$B$5:$B$10,MATCH(C11,Team!$A$5:$A$10,0)),"") -> Name 1 | E11: Sprint 1 - Accounts and Roles | F11: 3 | G11: LMS-101 | H11: High | I11: Done | K11: =IFERROR(INDEX(Team!$E$15:$E$21,MATCH(E11,Team!$A$15:$A$21,0)),"") -> 46318 | N11: =IF(AND(I11<>"Done",K11<>"",K11<TODAY()),"OVERDUE","") | O11: Provided in the starter repo - owner: read it, ask questions, improve via PR
A12: LMS-103 | B12: Student registration, login, logout and password reset (views + templates) | C12: BE-3 | D12: =IFERROR(INDEX(Team!$B$5:$B$10,MATCH(C12,Team!$A$5:$A$10,0)),"") -> Name 3 | E12: Sprint 1 - Accounts and Roles | F12: 6 | G12: LMS-101 | H12: High | I12: Not started | K12: =IFERROR(INDEX(Team!$E$15:$E$21,MATCH(E12,Team!$A$15:$A$21,0)),"") -> 46318 | N12: =IF(AND(I12<>"Done",K12<>"",K12<TODAY()),"OVERDUE","") | O12: Basic version in the starter repo - finish it
A13: LMS-104 | B13: Access-control mixins: RoleRequiredMixin, CourseManagerRequiredMixin | C13: BE-1 | D13: =IFERROR(INDEX(Team!$B$5:$B$10,MATCH(C13,Team!$A$5:$A$10,0)),"") -> Name 1 | E13: Sprint 1 - Accounts and Roles | F13: 4 | G13: LMS-102 | H13: High | I13: Done | K13: =IFERROR(INDEX(Team!$E$15:$E$21,MATCH(E13,Team!$A$15:$A$21,0)),"") -> 46318 | N13: =IF(AND(I13<>"Done",K13<>"",K13<TODAY()),"OVERDUE","") | O13: Provided in the starter repo - owner: read it, ask questions, improve via PR
A14: LMS-105 | B14: Admin user management: list, create facilitator, edit, activate/deactivate | C14: BE-2 | D14: =IFERROR(INDEX(Team!$B$5:$B$10,MATCH(C14,Team!$A$5:$A$10,0)),"") -> Name 2 | E14: Sprint 1 - Accounts and Roles | F14: 6 | G14: LMS-104 | H14: High | I14: Not started | K14: =IFERROR(INDEX(Team!$E$15:$E$21,MATCH(E14,Team!$A$15:$A$21,0)),"") -> 46318 | N14: =IF(AND(I14<>"Done",K14<>"",K14<TODAY()),"OVERDUE","")
A15: LMS-106 | B15: Admin facilitator list with grant / revoke 'can_manage_courses' button | C15: BE-2 | D15: =IFERROR(INDEX(Team!$B$5:$B$10,MATCH(C15,Team!$A$5:$A$10,0)),"") -> Name 2 | E15: Sprint 1 - Accounts and Roles | F15: 4 | G15: LMS-105 | H15: High | I15: Not started | K15: =IFERROR(INDEX(Team!$E$15:$E$21,MATCH(E15,Team!$A$15:$A$21,0)),"") -> 46318 | N15: =IF(AND(I15<>"Done",K15<>"",K15<TODAY()),"OVERDUE","")
A16: LMS-107 | B16: Profile view and edit pages for all roles | C16: FE | D16: =IFERROR(INDEX(Team!$B$5:$B$10,MATCH(C16,Team!$A$5:$A$10,0)),"") -> Name 4 | E16: Sprint 1 - Accounts and Roles | F16: 4 | G16: LMS-103 | H16: Medium | I16: Not started | K16: =IFERROR(INDEX(Team!$E$15:$E$21,MATCH(E16,Team!$A$15:$A$21,0)),"") -> 46318 | N16: =IF(AND(I16<>"Done",K16<>"",K16<TODAY()),"OVERDUE","")
A17: LMS-108 | B17: Dashboard redirect by role + three placeholder dashboards | C17: BE-3 | D17: =IFERROR(INDEX(Team!$B$5:$B$10,MATCH(C17,Team!$A$5:$A$10,0)),"") -> Name 3 | E17: Sprint 1 - Accounts and Roles | F17: 3 | G17: LMS-104 | H17: Medium | I17: Done | K17: =IFERROR(INDEX(Team!$E$15:$E$21,MATCH(E17,Team!$A$15:$A$21,0)),"") -> 46318 | N17: =IF(AND(I17<>"Done",K17<>"",K17<TODAY()),"OVERDUE","") | O17: Provided in the starter repo - owner: read it, ask questions, improve via PR
A18: LMS-109 | B18: Write tests: registration, login, role mixins, grant/revoke right | C18: QA | D18: =IFERROR(INDEX(Team!$B$5:$B$10,MATCH(C18,Team!$A$5:$A$10,0)),"") -> Name 5 | E18: Sprint 1 - Accounts and Roles | F18: 6 | G18: LMS-106 | H18: High | I18: Not started | K18: =IFERROR(INDEX(Team!$E$15:$E$21,MATCH(E18,Team!$A$15:$A$21,0)),"") -> 46318 | N18: =IF(AND(I18<>"Done",K18<>"",K18<TODAY()),"OVERDUE","")
A19: LMS-110 | B19: Management command create_demo_data (admin, facilitators, students, courses) | C19: BE-3 | D19: =IFERROR(INDEX(Team!$B$5:$B$10,MATCH(C19,Team!$A$5:$A$10,0)),"") -> Name 3 | E19: Sprint 1 - Accounts and Roles | F19: 3 | G19: LMS-102 | H19: Low | I19: Done | K19: =IFERROR(INDEX(Team!$E$15:$E$21,MATCH(E19,Team!$A$15:$A$21,0)),"") -> 46318 | N19: =IF(AND(I19<>"Done",K19<>"",K19<TODAY()),"OVERDUE","") | O19: Provided in the starter repo - owner: read it, ask questions, improve via PR
A20: LMS-111 | B20: Static HTML prototypes (home, course detail, dashboards) so pages are designed before the views exist | C20: FE | D20: =IFERROR(INDEX(Team!$B$5:$B$10,MATCH(C20,Team!$A$5:$A$10,0)),"") -> Name 4 | E20: Sprint 1 - Accounts and Roles | F20: 8 | G20: LMS-005 | H20: Medium | I20: Not started | K20: =IFERROR(INDEX(Team!$E$15:$E$21,MATCH(E20,Team!$A$15:$A$21,0)),"") -> 46318 | N20: =IF(AND(I20<>"Done",K20<>"",K20<TODAY()),"OVERDUE","")
A21: LMS-201 | B21: Course model, admin registration and migrations | C21: BE-2 | D21: =IFERROR(INDEX(Team!$B$5:$B$10,MATCH(C21,Team!$A$5:$A$10,0)),"") -> Name 2 | E21: Sprint 2 - Courses, Units and Home Page | F21: 3 | G21: LMS-104 | H21: High | I21: Done | K21: =IFERROR(INDEX(Team!$E$15:$E$21,MATCH(E21,Team!$A$15:$A$21,0)),"") -> 46332 | N21: =IF(AND(I21<>"Done",K21<>"",K21<TODAY()),"OVERDUE","") | O21: Provided in the starter repo - owner: read it, ask questions, improve via PR
A22: LMS-202 | B22: Unit model with facilitator FK and ordering | C22: BE-3 | D22: =IFERROR(INDEX(Team!$B$5:$B$10,MATCH(C22,Team!$A$5:$A$10,0)),"") -> Name 3 | E22: Sprint 2 - Courses, Units and Home Page | F22: 2 | G22: LMS-201 | H22: High | I22: Done | K22: =IFERROR(INDEX(Team!$E$15:$E$21,MATCH(E22,Team!$A$15:$A$21,0)),"") -> 46332 | N22: =IF(AND(I22<>"Done",K22<>"",K22<TODAY()),"OVERDUE","") | O22: Provided in the starter repo - owner: read it, ask questions, improve via PR
A23: LMS-203 | B23: Course create / update / delete views with ownership checks | C23: BE-2 | D23: =IFERROR(INDEX(Team!$B$5:$B$10,MATCH(C23,Team!$A$5:$A$10,0)),"") -> Name 2 | E23: Sprint 2 - Courses, Units and Home Page | F23: 8 | G23: LMS-201 | H23: High | I23: Not started | K23: =IFERROR(INDEX(Team!$E$15:$E$21,MATCH(E23,Team!$A$15:$A$21,0)),"") -> 46332 | N23: =IF(AND(I23<>"Done",K23<>"",K23<TODAY()),"OVERDUE","")
A24: LMS-204 | B24: Course form validation (dates, capacity) and image upload | C24: BE-3 | D24: =IFERROR(INDEX(Team!$B$5:$B$10,MATCH(C24,Team!$A$5:$A$10,0)),"") -> Name 3 | E24: Sprint 2 - Courses, Units and Home Page | F24: 3 | G24: LMS-203 | H24: Medium | I24: Not started | K24: =IFERROR(INDEX(Team!$E$15:$E$21,MATCH(E24,Team!$A$15:$A$21,0)),"") -> 46332 | N24: =IF(AND(I24<>"Done",K24<>"",K24<TODAY()),"OVERDUE","")
A25: LMS-205 | B25: Publish / close course action (status change) | C25: BE-3 | D25: =IFERROR(INDEX(Team!$B$5:$B$10,MATCH(C25,Team!$A$5:$A$10,0)),"") -> Name 3 | E25: Sprint 2 - Courses, Units and Home Page | F25: 2 | G25: LMS-203 | H25: High | I25: Not started | K25: =IFERROR(INDEX(Team!$E$15:$E$21,MATCH(E25,Team!$A$15:$A$21,0)),"") -> 46332 | N25: =IF(AND(I25<>"Done",K25<>"",K25<TODAY()),"OVERDUE","")
A26: LMS-206 | B26: Unit CRUD nested under a course + assign facilitator to unit | C26: BE-1 | D26: =IFERROR(INDEX(Team!$B$5:$B$10,MATCH(C26,Team!$A$5:$A$10,0)),"") -> Name 1 | E26: Sprint 2 - Courses, Units and Home Page | F26: 6 | G26: LMS-202 | H26: High | I26: Not started | K26: =IFERROR(INDEX(Team!$E$15:$E$21,MATCH(E26,Team!$A$15:$A$21,0)),"") -> 46332 | N26: =IF(AND(I26<>"Done",K26<>"",K26<TODAY()),"OVERDUE","")
A27: LMS-207 | B27: Home page: published course cards, search, filter, pagination | C27: FE | D27: =IFERROR(INDEX(Team!$B$5:$B$10,MATCH(C27,Team!$A$5:$A$10,0)),"") -> Name 4 | E27: Sprint 2 - Courses, Units and Home Page | F27: 8 | G27: LMS-205 | H27: High | I27: Not started | K27: =IFERROR(INDEX(Team!$E$15:$E$21,MATCH(E27,Team!$A$15:$A$21,0)),"") -> 46332 | N27: =IF(AND(I27<>"Done",K27<>"",K27<TODAY()),"OVERDUE","") | O27: Basic version in the starter repo - finish it
A28: LMS-208 | B28: Course detail page with unit list and smart 'Apply' button state | C28: FE | D28: =IFERROR(INDEX(Team!$B$5:$B$10,MATCH(C28,Team!$A$5:$A$10,0)),"") -> Name 4 | E28: Sprint 2 - Courses, Units and Home Page | F28: 5 | G28: LMS-205 | H28: High | I28: Not started | K28: =IFERROR(INDEX(Team!$E$15:$E$21,MATCH(E28,Team!$A$15:$A$21,0)),"") -> 46332 | N28: =IF(AND(I28<>"Done",K28<>"",K28<TODAY()),"OVERDUE","") | O28: Basic version in the starter repo - finish it
A29: LMS-209 | B29: 'Manage courses' table page for admin and course managers | C29: FE | D29: =IFERROR(INDEX(Team!$B$5:$B$10,MATCH(C29,Team!$A$5:$A$10,0)),"") -> Name 4 | E29: Sprint 2 - Courses, Units and Home Page | F29: 4 | G29: LMS-203 | H29: Medium | I29: Not started | K29: =IFERROR(INDEX(Team!$E$15:$E$21,MATCH(E29,Team!$A$15:$A$21,0)),"") -> 46332 | N29: =IF(AND(I29<>"Done",K29<>"",K29<TODAY()),"OVERDUE","")
A30: LMS-210 | B30: 'My units' page for facilitators (units I teach) | C30: BE-1 | D30: =IFERROR(INDEX(Team!$B$5:$B$10,MATCH(C30,Team!$A$5:$A$10,0)),"") -> Name 1 | E30: Sprint 2 - Courses, Units and Home Page | F30: 3 | G30: LMS-206 | H30: Medium | I30: Not started | K30: =IFERROR(INDEX(Team!$E$15:$E$21,MATCH(E30,Team!$A$15:$A$21,0)),"") -> 46332 | N30: =IF(AND(I30<>"Done",K30<>"",K30<TODAY()),"OVERDUE","")
A31: LMS-211 | B31: Tests: who can create / edit / delete, unpublished courses hidden from home | C31: QA | D31: =IFERROR(INDEX(Team!$B$5:$B$10,MATCH(C31,Team!$A$5:$A$10,0)),"") -> Name 5 | E31: Sprint 2 - Courses, Units and Home Page | F31: 8 | G31: LMS-207 | H31: High | I31: Not started | K31: =IFERROR(INDEX(Team!$E$15:$E$21,MATCH(E31,Team!$A$15:$A$21,0)),"") -> 46332 | N31: =IF(AND(I31<>"Done",K31<>"",K31<TODAY()),"OVERDUE","")
A32: LMS-301 | B32: Application model with unique (student, course) constraint | C32: BE-3 | D32: =IFERROR(INDEX(Team!$B$5:$B$10,MATCH(C32,Team!$A$5:$A$10,0)),"") -> Name 3 | E32: Sprint 3 - Applications and Enrollment | F32: 2 | G32: LMS-201 | H32: High | I32: Done | K32: =IFERROR(INDEX(Team!$E$15:$E$21,MATCH(E32,Team!$A$15:$A$21,0)),"") -> 46339 | N32: =IF(AND(I32<>"Done",K32<>"",K32<TODAY()),"OVERDUE","") | O32: Provided in the starter repo - owner: read it, ask questions, improve via PR
A33: LMS-302 | B33: Enrollment model | C33: BE-3 | D33: =IFERROR(INDEX(Team!$B$5:$B$10,MATCH(C33,Team!$A$5:$A$10,0)),"") -> Name 3 | E33: Sprint 3 - Applications and Enrollment | F33: 2 | G33: LMS-301 | H33: High | I33: Done | K33: =IFERROR(INDEX(Team!$E$15:$E$21,MATCH(E33,Team!$A$15:$A$21,0)),"") -> 46339 | N33: =IF(AND(I33<>"Done",K33<>"",K33<TODAY()),"OVERDUE","") | O33: Provided in the starter repo - owner: read it, ask questions, improve via PR
A34: LMS-303 | B34: Apply view + form; rules: window open, capacity, no duplicates | C34: BE-2 | D34: =IFERROR(INDEX(Team!$B$5:$B$10,MATCH(C34,Team!$A$5:$A$10,0)),"") -> Name 2 | E34: Sprint 3 - Applications and Enrollment | F34: 5 | G34: LMS-301 | H34: High | I34: Not started | K34: =IFERROR(INDEX(Team!$E$15:$E$21,MATCH(E34,Team!$A$15:$A$21,0)),"") -> 46339 | N34: =IF(AND(I34<>"Done",K34<>"",K34<TODAY()),"OVERDUE","")
A35: LMS-304 | B35: 'My applications' page with withdraw button | C35: FE | D35: =IFERROR(INDEX(Team!$B$5:$B$10,MATCH(C35,Team!$A$5:$A$10,0)),"") -> Name 4 | E35: Sprint 3 - Applications and Enrollment | F35: 4 | G35: LMS-303 | H35: Medium | I35: Not started | K35: =IFERROR(INDEX(Team!$E$15:$E$21,MATCH(E35,Team!$A$15:$A$21,0)),"") -> 46339 | N35: =IF(AND(I35<>"Done",K35<>"",K35<TODAY()),"OVERDUE","")
A36: LMS-305 | B36: Manage applications list with filters (status, course) | C36: BE-3 | D36: =IFERROR(INDEX(Team!$B$5:$B$10,MATCH(C36,Team!$A$5:$A$10,0)),"") -> Name 3 | E36: Sprint 3 - Applications and Enrollment | F36: 5 | G36: LMS-301 | H36: High | I36: Not started | K36: =IFERROR(INDEX(Team!$E$15:$E$21,MATCH(E36,Team!$A$15:$A$21,0)),"") -> 46339 | N36: =IF(AND(I36<>"Done",K36<>"",K36<TODAY()),"OVERDUE","")
A37: LMS-306 | B37: Approve / reject with note; service function creates Enrollment | C37: BE-1 | D37: =IFERROR(INDEX(Team!$B$5:$B$10,MATCH(C37,Team!$A$5:$A$10,0)),"") -> Name 1 | E37: Sprint 3 - Applications and Enrollment | F37: 5 | G37: LMS-302 | H37: High | I37: Not started | K37: =IFERROR(INDEX(Team!$E$15:$E$21,MATCH(E37,Team!$A$15:$A$21,0)),"") -> 46339 | N37: =IF(AND(I37<>"Done",K37<>"",K37<TODAY()),"OVERDUE","")
A38: LMS-307 | B38: Email on decision (console backend in dev, SMTP in prod) | C38: BE-3 | D38: =IFERROR(INDEX(Team!$B$5:$B$10,MATCH(C38,Team!$A$5:$A$10,0)),"") -> Name 3 | E38: Sprint 3 - Applications and Enrollment | F38: 3 | G38: LMS-306 | H38: Low | I38: Not started | K38: =IFERROR(INDEX(Team!$E$15:$E$21,MATCH(E38,Team!$A$15:$A$21,0)),"") -> 46339 | N38: =IF(AND(I38<>"Done",K38<>"",K38<TODAY()),"OVERDUE","")
A39: LMS-308 | B39: Student 'My courses' page + facilitator unit roster | C39: FE | D39: =IFERROR(INDEX(Team!$B$5:$B$10,MATCH(C39,Team!$A$5:$A$10,0)),"") -> Name 4 | E39: Sprint 3 - Applications and Enrollment | F39: 5 | G39: LMS-306 | H39: Medium | I39: Not started | K39: =IFERROR(INDEX(Team!$E$15:$E$21,MATCH(E39,Team!$A$15:$A$21,0)),"") -> 46339 | N39: =IF(AND(I39<>"Done",K39<>"",K39<TODAY()),"OVERDUE","")
A40: LMS-309 | B40: Tests: apply rules, approval flow, capacity edge cases | C40: QA | D40: =IFERROR(INDEX(Team!$B$5:$B$10,MATCH(C40,Team!$A$5:$A$10,0)),"") -> Name 5 | E40: Sprint 3 - Applications and Enrollment | F40: 6 | G40: LMS-306 | H40: High | I40: Not started | K40: =IFERROR(INDEX(Team!$E$15:$E$21,MATCH(E40,Team!$A$15:$A$21,0)),"") -> 46339 | N40: =IF(AND(I40<>"Done",K40<>"",K40<TODAY()),"OVERDUE","")
...
